<?xml version="1.0"?>
<robot name="exoarm">

    <!-- Links:-->
    <!-- Upper Arm-->
    <link name = "upperarm">
        <collision>
            <origin xyz="0.0 0.0 -0.2" rpy="0.0 0.0 0.0"/>
            <geometry>
                <cylinder radius="0.07" length="0.4" />
            </geometry>
        </collision>

        <visual>
            <origin xyz="0.0 0.0 -0.2" rpy="0.0 0.0 0.0"/>
            <geometry>
                <cylinder radius="0.07" length="0.4" />
            </geometry>
        </visual>

        <inertial>
            <origin xyz="0 0 0.2" rpy="0 0 0"/>
            <mass value="1"/>
            <inertia
              ixx="1.0" ixy="0.0" ixz="0.0"
              iyy="1.0" iyz="0.0"
              izz="1.0"/>
        </inertial>
    </link>

    <!-- Lower Arm-->
    <link name = "lowerarm">
        <collision>
            <origin xyz="0.0 0.0 0.16" rpy="0.0 0.0 0.0"/>
            <geometry>
                <cylinder radius="0.06" length="0.35" />
            </geometry>
        </collision>

        <visual>
            <origin xyz="0.0 0.0 0.16" rpy="0.0 0.0 0.0"/>
            <geometry>
                <cylinder radius="0.06" length="0.35" />
            </geometry>
        </visual>

        <inertial>
            <origin xyz="0 0 0.16" rpy="0 0 0"/>
            <mass value="1"/>
            <inertia
              ixx="1.0" ixy="0.0" ixz="0.0"
              iyy="1.0" iyz="0.0"
              izz="1.0"/>
        </inertial>
    </link>

    <!-- Joints:-->
    <!-- Elbow joint-->
    <joint name = "elbow" type = "continuous">
        <parent link = "upperarm"/>
        <child link = "lowerarm"/>
        <origin xyz = "0 0 0" rpy = "0 0 0"/>

        <axis xyz = "0 1 0"/>
        <limit effort="1000.0" lower="0.0" upper="2.0"/>
        <dynamics damping = "0.7"/>
    </joint>

</robot>