<?xml version="1.0"?>
<robot name="exo_arm">
<!-- definities onderdelen-->

  <!-- bovenarm-->
  <link name="upper_arm">
    <collision>
      <geometry>
        <cylinder radius="0.07" length="0.4" />
      </geometry>
    </collision>
    <visual>
      <origin xyz="0.0 0.0 -0.2" rpy="0.0 0.0 0.0"/>
      <geometry>
        <cylinder radius="0.07" length="0.4" />
      </geometry>
    </visual>
  </link>

  <!-- onderarm-->
  <link name="under_arm">
      <collision>
        <geometry>
          <cylinder radius="0.06" length="0.35" />
        </geometry>
      </collision>
      <visual>
        <origin xyz="0.0 0.0 0.16" rpy="0.0 0.0 0.0"/>
        <geometry>
          <cylinder radius="0.06" length="0.4" />
        </geometry>
      </visual>
    </link>

  <!-- elleboog definitie en settings-->
  <joint name="elbow" type="continuous">
    <limit effort="1000.0" lower="0.0" upper="2.0"/>
    <parent link="upper_arm"/>
    <child link="under_arm"/>
    <axis xyz="1 0 0"/>
  </joint>

</robot>